<?xml version="1.0" ?>
<robot name="arm" xmlns:xacro="http://www.ros.org/wiki/xacro">

<xacro:include filename="$(find arm_description)/urdf/materials.xacro" />
<xacro:include filename="$(find arm_description)/urdf/arm.trans" />
<link name="base_link">
  <inertial>
    <origin xyz="-0.035332029911054406 -0.0001151713095156251 0.01677047618232762" rpy="0 0 0"/>
    <mass value="1.0722770152321714"/>
    <inertia ixx="0.000458" iyy="0.001782" izz="0.001902" ixy="-4e-06" iyz="-2e-06" ixz="0.000177"/>
  </inertial>
  <visual>
    <origin xyz="0 0 0" rpy="0 0 0"/>
    <geometry>
      <mesh filename="/home/ritwik/vallab_ws/src/arm_description/meshes/STL/CAD/base_link.stl" scale="0.001 0.001 0.001"/>
    </geometry>
    <material name="opaque210200"/>
  </visual>
  <collision>
    <origin xyz="0 0 0" rpy="0 0 0"/>
    <geometry>
      <mesh filename="/home/ritwik/vallab_ws/src/arm_description/meshes/STL/CAD/base_link.stl" scale="0.001 0.001 0.001"/>
    </geometry>
  </collision>
</link>

<link name="link11">
  <inertial>
    <origin xyz="6.245004513516506e-16 4.29525355211143e-07 0.008489399860949962" rpy="0 0 0"/>
    <mass value="0.03750981375662675"/>
    <inertia ixx="2e-06" iyy="2e-06" izz="2e-06" ixy="-0.0" iyz="-0.0" ixz="0.0"/>
  </inertial>
  <visual>
    <origin xyz="0.069 -0.0 -0.006" rpy="0 0 0"/>
    <geometry>
      <mesh filename="/home/ritwik/vallab_ws/src/arm_description/meshes/STL/CAD/link11.stl" scale="0.001 0.001 0.001"/>
    </geometry>
    <material name="opaque160160160"/>
  </visual>
  <collision>
    <origin xyz="0.069 -0.0 -0.006" rpy="0 0 0"/>
    <geometry>
      <mesh filename="/home/ritwik/vallab_ws/src/arm_description/meshes/STL/CAD/link11.stl" scale="0.001 0.001 0.001"/>
    </geometry>
  </collision>
</link>

<link name="link1">
  <inertial>
    <origin xyz="0.011206111393191323 -0.00011244258381883525 0.0356863108174146" rpy="0 0 0"/>
    <mass value="1.2482750398529938"/>
    <inertia ixx="0.000783" iyy="0.001096" izz="0.000998" ixy="3e-06" iyz="3e-06" ixz="-0.000187"/>
  </inertial>
  <visual>
    <origin xyz="0.0 0.0 -0.0105" rpy="0 0 0"/>
    <geometry>
      <mesh filename="/home/ritwik/vallab_ws/src/arm_description/meshes/STL/CAD/link1.stl" scale="0.001 0.001 0.001"/>
    </geometry>
    <material name="opaque210200"/>
  </visual>
  <collision>
    <origin xyz="0.0 0.0 -0.0105" rpy="0 0 0"/>
    <geometry>
      <mesh filename="/home/ritwik/vallab_ws/src/arm_description/meshes/STL/CAD/link1.stl" scale="0.001 0.001 0.001"/>
    </geometry>
  </collision>
</link>

<link name="link2">
  <inertial>
    <origin xyz="-0.10533457699711699 0.01592298495871186 0.0025359722344356073" rpy="0 0 0"/>
    <mass value="1.5172780004261823"/>
    <inertia ixx="0.000757" iyy="0.00883" izz="0.009159" ixy="6.7e-05" iyz="2e-06" ixz="-4e-05"/>
  </inertial>
  <visual>
    <origin xyz="-0.045 0.017 -0.062" rpy="0 0 0"/>
    <geometry>
      <mesh filename="/home/ritwik/vallab_ws/src/arm_description/meshes/STL/CAD/link2.stl" scale="0.001 0.001 0.001"/>
    </geometry>
    <material name="opaque252525"/>
  </visual>
  <collision>
    <origin xyz="-0.045 0.017 -0.062" rpy="0 0 0"/>
    <geometry>
      <mesh filename="/home/ritwik/vallab_ws/src/arm_description/meshes/STL/CAD/link2.stl" scale="0.001 0.001 0.001"/>
    </geometry>
  </collision>
</link>

<link name="link3">
  <inertial>
    <origin xyz="0.05688940039684258 0.016684826028364724 0.017232609352887562" rpy="0 0 0"/>
    <mass value="0.6382129609796608"/>
    <inertia ixx="0.000266" iyy="0.000647" izz="0.000695" ixy="-6e-06" iyz="-2e-06" ixz="-0.000136"/>
  </inertial>
  <visual>
    <origin xyz="0.155 0.017 -0.077" rpy="0 0 0"/>
    <geometry>
      <mesh filename="/home/ritwik/vallab_ws/src/arm_description/meshes/STL/CAD/link3.stl" scale="0.001 0.001 0.001"/>
    </geometry>
    <material name="opaque210200"/>
  </visual>
  <collision>
    <origin xyz="0.155 0.017 -0.077" rpy="0 0 0"/>
    <geometry>
      <mesh filename="/home/ritwik/vallab_ws/src/arm_description/meshes/STL/CAD/link3.stl" scale="0.001 0.001 0.001"/>
    </geometry>
  </collision>
</link>

<link name="link4">
  <inertial>
    <origin xyz="0.02539855845508478 -2.4088588287602283e-07 2.4485807587071307e-07" rpy="0 0 0"/>
    <mass value="0.556203439123278"/>
    <inertia ixx="0.000498" iyy="0.000461" izz="0.00092" ixy="-0.0" iyz="0.0" ixz="-0.0"/>
  </inertial>
  <visual>
    <origin xyz="0.0461 0.0 -0.103" rpy="0 0 0"/>
    <geometry>
      <mesh filename="/home/ritwik/vallab_ws/src/arm_description/meshes/STL/CAD/link4.stl" scale="0.001 0.001 0.001"/>
    </geometry>
    <material name="opaque252525"/>
  </visual>
  <collision>
    <origin xyz="0.0461 0.0 -0.103" rpy="0 0 0"/>
    <geometry>
      <mesh filename="/home/ritwik/vallab_ws/src/arm_description/meshes/STL/CAD/link4.stl" scale="0.001 0.001 0.001"/>
    </geometry>
  </collision>
</link>

<link name="link5">
  <inertial>
    <origin xyz="2.753202211509126e-07 0.005524662132598862 -1.7395752630045003e-08" rpy="0 0 0"/>
    <mass value="0.048347571885136914"/>
    <inertia ixx="4e-06" iyy="8e-06" izz="4e-06" ixy="0.0" iyz="0.0" ixz="-0.0"/>
  </inertial>
  <visual>
    <origin xyz="-0.0108 0.024 -0.103" rpy="0 0 0"/>
    <geometry>
      <mesh filename="/home/ritwik/vallab_ws/src/arm_description/meshes/STL/CAD/link5.stl" scale="0.001 0.001 0.001"/>
    </geometry>
    <material name="opaque210200"/>
  </visual>
  <collision>
    <origin xyz="-0.0108 0.024 -0.103" rpy="0 0 0"/>
    <geometry>
      <mesh filename="/home/ritwik/vallab_ws/src/arm_description/meshes/STL/CAD/link5.stl" scale="0.001 0.001 0.001"/>
    </geometry>
  </collision>
</link>

<link name="link6">
  <inertial>
    <origin xyz="2.7532022249358856e-07 -0.0055246621326002915 -1.7395751616966493e-08" rpy="0 0 0"/>
    <mass value="0.04834757188513691"/>
    <inertia ixx="4e-06" iyy="8e-06" izz="4e-06" ixy="-0.0" iyz="-0.0" ixz="-0.0"/>
  </inertial>
  <visual>
    <origin xyz="-0.0108 -0.024 -0.103" rpy="0 0 0"/>
    <geometry>
      <mesh filename="/home/ritwik/vallab_ws/src/arm_description/meshes/STL/CAD/link6.stl" scale="0.001 0.001 0.001"/>
    </geometry>
    <material name="opaque210200"/>
  </visual>
  <collision>
    <origin xyz="-0.0108 -0.024 -0.103" rpy="0 0 0"/>
    <geometry>
      <mesh filename="/home/ritwik/vallab_ws/src/arm_description/meshes/STL/CAD/link6.stl" scale="0.001 0.001 0.001"/>
    </geometry>
  </collision>
</link>

<link name="link7">
  <inertial>
    <origin xyz="0.0028448480020698153 -0.02399986356623937 -2.0958257078984577e-06" rpy="0 0 0"/>
    <mass value="0.15678652750508332"/>
    <inertia ixx="3.8e-05" iyy="3.9e-05" izz="3.5e-05" ixy="-0.0" iyz="0.0" ixz="-0.0"/>
  </inertial>
  <visual>
    <origin xyz="-0.0108 -0.024 -0.103" rpy="0 0 0"/>
    <geometry>
      <mesh filename="/home/ritwik/vallab_ws/src/arm_description/meshes/STL/CAD/link7.stl" scale="0.001 0.001 0.001"/>
    </geometry>
    <material name="opaque160160160"/>
  </visual>
  <collision>
    <origin xyz="-0.0108 -0.024 -0.103" rpy="0 0 0"/>
    <geometry>
      <mesh filename="/home/ritwik/vallab_ws/src/arm_description/meshes/STL/CAD/link7.stl" scale="0.001 0.001 0.001"/>
    </geometry>
  </collision>
</link>

<link name="link8">
  <inertial>
    <origin xyz="0.006337791282976783 0.014437861844293989 -0.002533555574269944" rpy="0 0 0"/>
    <mass value="0.41604327739339353"/>
    <inertia ixx="0.000417" iyy="0.000227" izz="0.000586" ixy="-1.7e-05" iyz="3.7e-05" ixz="6e-06"/>
  </inertial>
  <visual>
    <origin xyz="-0.0328 0.0 -0.103" rpy="0 0 0"/>
    <geometry>
      <mesh filename="/home/ritwik/vallab_ws/src/arm_description/meshes/STL/CAD/link8.stl" scale="0.001 0.001 0.001"/>
    </geometry>
    <material name="opaque210200"/>
  </visual>
  <collision>
    <origin xyz="-0.0328 0.0 -0.103" rpy="0 0 0"/>
    <geometry>
      <mesh filename="/home/ritwik/vallab_ws/src/arm_description/meshes/STL/CAD/link8.stl" scale="0.001 0.001 0.001"/>
    </geometry>
  </collision>
</link>

<link name="link12">
  <inertial>
    <origin xyz="-0.0070040483790297925 -8.487575241938883e-08 -8.071878474513738e-07" rpy="0 0 0"/>
    <mass value="0.019850481866978086"/>
    <inertia ixx="1e-06" iyy="1e-06" izz="1e-06" ixy="-0.0" iyz="0.0" ixz="-0.0"/>
  </inertial>
  <visual>
    <origin xyz="-0.0664 -0.05 -0.103" rpy="0 0 0"/>
    <geometry>
      <mesh filename="/home/ritwik/vallab_ws/src/arm_description/meshes/STL/CAD/link12.stl" scale="0.001 0.001 0.001"/>
    </geometry>
    <material name="opaque898989"/>
  </visual>
  <collision>
    <origin xyz="-0.0664 -0.05 -0.103" rpy="0 0 0"/>
    <geometry>
      <mesh filename="/home/ritwik/vallab_ws/src/arm_description/meshes/STL/CAD/link12.stl" scale="0.001 0.001 0.001"/>
    </geometry>
  </collision>
</link>

<link name="link10">
  <inertial>
    <origin xyz="0.02573313617415028 -0.03390025109466069 0.0052187897794312155" rpy="0 0 0"/>
    <mass value="0.1633987484930479"/>
    <inertia ixx="3.2e-05" iyy="7.7e-05" izz="7.6e-05" ixy="1.2e-05" iyz="5e-06" ixz="-8e-06"/>
  </inertial>
  <visual>
    <origin xyz="-0.0641 -0.0325 -0.0959" rpy="0 0 0"/>
    <geometry>
      <mesh filename="/home/ritwik/vallab_ws/src/arm_description/meshes/STL/CAD/link10.stl" scale="0.001 0.001 0.001"/>
    </geometry>
    <material name="opaque252525"/>
  </visual>
  <collision>
    <origin xyz="-0.0641 -0.0325 -0.0959" rpy="0 0 0"/>
    <geometry>
      <mesh filename="/home/ritwik/vallab_ws/src/arm_description/meshes/STL/CAD/link10.stl" scale="0.001 0.001 0.001"/>
    </geometry>
  </collision>
</link>

<link name="link9">
  <inertial>
    <origin xyz="0.0257331361554268 0.033900251075823624 -0.005218789736564436" rpy="0 0 0"/>
    <mass value="0.16339874859628656"/>
    <inertia ixx="3.2e-05" iyy="7.7e-05" izz="7.6e-05" ixy="-1.2e-05" iyz="5e-06" ixz="8e-06"/>
  </inertial>
  <visual>
    <origin xyz="-0.0641 0.0325 -0.1101" rpy="0 0 0"/>
    <geometry>
      <mesh filename="/home/ritwik/vallab_ws/src/arm_description/meshes/STL/CAD/link9.stl" scale="0.001 0.001 0.001"/>
    </geometry>
    <material name="opaque1965339"/>
  </visual>
  <collision>
    <origin xyz="-0.0641 0.0325 -0.1101" rpy="0 0 0"/>
    <geometry>
      <mesh filename="/home/ritwik/vallab_ws/src/arm_description/meshes/STL/CAD/link9.stl" scale="0.001 0.001 0.001"/>
    </geometry>
  </collision>
</link>

<joint name="base_link-link11" type="continuous">
  <origin xyz="-0.069 0.0 0.006" rpy="0 0 0"/>
  <parent link="base_link"/>
  <child link="link11"/>
  <axis xyz="0.0 0.0 1.0"/>
</joint>

<joint name="base_link-link1" type="revolute">
  <origin xyz="0.0 0.0 0.0105" rpy="0 0 0"/>
  <parent link="base_link"/>
  <child link="link1"/>
  <axis xyz="0.0 0.0 1.0"/>
  <limit upper="3.141593" lower="-3.141593" effort="100" velocity="100"/>
</joint>

<joint name="link1-link2" type="revolute">
  <origin xyz="0.045 -0.017 0.0515" rpy="0 0 0"/>
  <parent link="link1"/>
  <child link="link2"/>
  <axis xyz="0.0 1.0 0.0"/>
  <limit upper="4.101524" lower="0.0" effort="100" velocity="100"/>
</joint>

<joint name="link2-link3" type="revolute">
  <origin xyz="-0.2 0.0 0.015" rpy="0 0 0"/>
  <parent link="link2"/>
  <child link="link3"/>
  <axis xyz="0.0 1.0 0.0"/>
  <limit upper="0.0" lower="-2.792527" effort="100" velocity="100"/>
</joint>

<joint name="link3-link4" type="revolute">
  <origin xyz="0.1089 0.017 0.026" rpy="0 0 0"/>
  <parent link="link3"/>
  <child link="link4"/>
  <axis xyz="1.0 0.0 0.0"/>
  <limit upper="3.141593" lower="-3.141593" effort="100" velocity="100"/>
</joint>

<joint name="link4-link5" type="continuous">
  <origin xyz="0.0569 -0.024 0.0" rpy="0 0 0"/>
  <parent link="link4"/>
  <child link="link5"/>
  <axis xyz="0.0 1.0 0.0"/>
</joint>

<joint name="link4-link6" type="continuous">
  <origin xyz="0.0569 0.024 0.0" rpy="0 0 0"/>
  <parent link="link4"/>
  <child link="link6"/>
  <axis xyz="0.0 1.0 0.0"/>
</joint>

<joint name="link4-link7" type="revolute">
  <origin xyz="0.0569 0.024 0.0" rpy="0 0 0"/>
  <parent link="link4"/>
  <child link="link7"/>
  <axis xyz="0.0 1.0 0.0"/>
  <limit upper="1.745329" lower="-1.745329" effort="100" velocity="100"/>
</joint>

<joint name="link7-link8" type="revolute">
  <origin xyz="0.022 -0.024 0.0" rpy="0 0 0"/>
  <parent link="link7"/>
  <child link="link8"/>
  <axis xyz="1.0 0.0 0.0"/>
  <limit upper="3.141593" lower="-3.141593" effort="100" velocity="100"/>
</joint>

<joint name="link8-link12" type="continuous">
  <origin xyz="0.0336 0.05 0.0" rpy="0 0 0"/>
  <parent link="link8"/>
  <child link="link12"/>
  <axis xyz="1.0 0.0 0.0"/>
</joint>

<joint name="link8-link10" type="prismatic">
  <origin xyz="0.0313 0.0325 -0.0071" rpy="0 0 0"/>
  <parent link="link8"/>
  <child link="link10"/>
  <axis xyz="0.0 1.0 0.0"/>
  <limit upper="0.0" lower="-0.051" effort="100" velocity="100"/>
</joint>

<joint name="link8-link9" type="prismatic">
  <origin xyz="0.0313 -0.0325 0.0071" rpy="0 0 0"/>
  <parent link="link8"/>
  <child link="link9"/>
  <axis xyz="0.0 1.0 0.0"/>
  <limit upper="0.051" lower="0.0" effort="100" velocity="100"/>
</joint>

</robot>
