<?xml version="1.0" ?>
<robot name="arm" >

    <material name="silver_default">
        <color rgba="0.700 0.700 0.700 1.000"/>
    </material>
    <material name="opaque210200">
        <color rgba="0.8235294117647058 0.0784313725490196 0.0 1.0"/>
    </material>
    <material name="opaque252525">
        <color rgba="0.09803921568627451 0.09803921568627451 0.09803921568627451 1.0"/>
    </material>
    <material name="opaque160160160">
        <color rgba="0.6274509803921569 0.6274509803921569 0.6274509803921569 1.0"/>
    </material>
    <material name="opaque1965339">
        <color rgba="0.7686274509803922 0.20784313725490197 0.15294117647058825 1.0"/>
    </material>
    <material name="opaque898989">
        <color rgba="0.34901960784313724 0.34901960784313724 0.34901960784313724 1.0"/>
    </material>

<link name="base_link">
  <inertial>
    <origin xyz="-0.035332029911054406 -0.0001151713095156251 0.01677047618232762" rpy="0 0 0"/>
    <mass value="1.0722770152321714"/>
    <inertia ixx="0.000458" iyy="0.001782" izz="0.001902" ixy="-4e-06" iyz="-2e-06" ixz="0.000177"/>
  </inertial>
  <visual>
    <origin xyz="0 0 0" rpy="0 0 0"/>
    <geometry>
      <mesh filename="package://arm_description/meshes/STL/VDB/base_link.stl" scale="0.001 0.001 0.001"/>
    </geometry>
    <material name="opaque210200"/>
  </visual>
  <collision>
    <origin xyz="0 0 0" rpy="0 0 0"/>
    <geometry>
      <mesh filename="package://arm_description/meshes/STL/VDB/base_link.stl" scale="0.001 0.001 0.001"/>
    </geometry>
  </collision>
</link>

<link name="link11">
  <inertial>
    <origin xyz="6.245004513516506e-16 4.29525355211143e-07 0.008489399860949962" rpy="0 0 0"/>
    <mass value="0.03750981375662675"/>
    <inertia ixx="2e-06" iyy="2e-06" izz="2e-06" ixy="-0.0" iyz="-0.0" ixz="0.0"/>
  </inertial>
  <visual>
    <origin xyz="0.069 -0.0 -0.006" rpy="0 0 0"/>
    <geometry>
      <mesh filename="package://arm_description/meshes/STL/VDB/link11.stl" scale="0.001 0.001 0.001"/>
    </geometry>
    <material name="opaque160160160"/>
  </visual>
  <collision>
    <origin xyz="0.069 -0.0 -0.006" rpy="0 0 0"/>
    <geometry>
      <mesh filename="package://arm_description/meshes/STL/VDB/link11.stl" scale="0.001 0.001 0.001"/>
    </geometry>
  </collision>
</link>

<link name="link1">
  <inertial>
    <origin xyz="0.011206111393191323 -0.00011244258381883525 0.0356863108174146" rpy="0 0 0"/>
    <mass value="1.2482750398529938"/>
    <inertia ixx="0.000783" iyy="0.001096" izz="0.000998" ixy="3e-06" iyz="3e-06" ixz="-0.000187"/>
  </inertial>
  <visual>
    <origin xyz="0.0 0.0 -0.0105" rpy="0 0 0"/>
    <geometry>
      <mesh filename="package://arm_description/meshes/STL/VDB/link1.stl" scale="0.001 0.001 0.001"/>
    </geometry>
    <material name="opaque210200"/>
  </visual>
  <collision>
    <origin xyz="0.0 0.0 -0.0105" rpy="0 0 0"/>
    <geometry>
      <mesh filename="package://arm_description/meshes/STL/VDB/link1.stl" scale="0.001 0.001 0.001"/>
    </geometry>
  </collision>
</link>

<link name="link2">
  <inertial>
    <origin xyz="-0.10533457699711699 0.01592298495871186 0.0025359722344356073" rpy="0 0 0"/>
    <mass value="1.5172780004261823"/>
    <inertia ixx="0.000757" iyy="0.00883" izz="0.009159" ixy="6.7e-05" iyz="2e-06" ixz="-4e-05"/>
  </inertial>
  <visual>
    <origin xyz="-0.045 0.017 -0.062" rpy="0 0 0"/>
    <geometry>
      <mesh filename="package://arm_description/meshes/STL/VDB/link2.stl" scale="0.001 0.001 0.001"/>
    </geometry>
    <material name="opaque252525"/>
  </visual>
  <collision>
    <origin xyz="-0.045 0.017 -0.062" rpy="0 0 0"/>
    <geometry>
      <mesh filename="package://arm_description/meshes/STL/VDB/link2.stl" scale="0.001 0.001 0.001"/>
    </geometry>
  </collision>
</link>

<link name="link3">
  <inertial>
    <origin xyz="0.05688940039684258 0.016684826028364724 0.017232609352887562" rpy="0 0 0"/>
    <mass value="0.6382129609796608"/>
    <inertia ixx="0.000266" iyy="0.000647" izz="0.000695" ixy="-6e-06" iyz="-2e-06" ixz="-0.000136"/>
  </inertial>
  <visual>
    <origin xyz="0.155 0.017 -0.077" rpy="0 0 0"/>
    <geometry>
      <mesh filename="package://arm_description/meshes/STL/VDB/link3.stl" scale="0.001 0.001 0.001"/>
    </geometry>
    <material name="opaque210200"/>
  </visual>
  <collision>
    <origin xyz="0.155 0.017 -0.077" rpy="0 0 0"/>
    <geometry>
      <mesh filename="package://arm_description/meshes/STL/VDB/link3.stl" scale="0.001 0.001 0.001"/>
    </geometry>
  </collision>
</link>

<link name="link4">
  <inertial>
    <origin xyz="0.02539855845508478 -2.4088588287602283e-07 2.4485807587071307e-07" rpy="0 0 0"/>
    <mass value="0.556203439123278"/>
    <inertia ixx="0.000498" iyy="0.000461" izz="0.00092" ixy="-0.0" iyz="0.0" ixz="-0.0"/>
  </inertial>
  <visual>
    <origin xyz="0.0461 0.0 -0.103" rpy="0 0 0"/>
    <geometry>
      <mesh filename="package://arm_description/meshes/STL/VDB/link4.stl" scale="0.001 0.001 0.001"/>
    </geometry>
    <material name="opaque252525"/>
  </visual>
  <collision>
    <origin xyz="0.0461 0.0 -0.103" rpy="0 0 0"/>
    <geometry>
      <mesh filename="package://arm_description/meshes/STL/VDB/link4.stl" scale="0.001 0.001 0.001"/>
    </geometry>
  </collision>
</link>

<link name="link5">
  <inertial>
    <origin xyz="2.753202211509126e-07 0.005524662132598862 -1.7395752630045003e-08" rpy="0 0 0"/>
    <mass value="0.048347571885136914"/>
    <inertia ixx="4e-06" iyy="8e-06" izz="4e-06" ixy="0.0" iyz="0.0" ixz="-0.0"/>
  </inertial>
  <visual>
    <origin xyz="-0.0108 0.024 -0.103" rpy="0 0 0"/>
    <geometry>
      <mesh filename="package://arm_description/meshes/STL/VDB/link5.stl" scale="0.001 0.001 0.001"/>
    </geometry>
    <material name="opaque210200"/>
  </visual>
  <collision>
    <origin xyz="-0.0108 0.024 -0.103" rpy="0 0 0"/>
    <geometry>
      <mesh filename="package://arm_description/meshes/STL/VDB/link5.stl" scale="0.001 0.001 0.001"/>
    </geometry>
  </collision>
</link>

<link name="link6">
  <inertial>
    <origin xyz="2.7532022249358856e-07 -0.0055246621326002915 -1.7395751616966493e-08" rpy="0 0 0"/>
    <mass value="0.04834757188513691"/>
    <inertia ixx="4e-06" iyy="8e-06" izz="4e-06" ixy="-0.0" iyz="-0.0" ixz="-0.0"/>
  </inertial>
  <visual>
    <origin xyz="-0.0108 -0.024 -0.103" rpy="0 0 0"/>
    <geometry>
      <mesh filename="package://arm_description/meshes/STL/VDB/link6.stl" scale="0.001 0.001 0.001"/>
    </geometry>
    <material name="opaque210200"/>
  </visual>
  <collision>
    <origin xyz="-0.0108 -0.024 -0.103" rpy="0 0 0"/>
    <geometry>
      <mesh filename="package://arm_description/meshes/STL/VDB/link6.stl" scale="0.001 0.001 0.001"/>
    </geometry>
  </collision>
</link>

<link name="link7">
  <inertial>
    <origin xyz="0.0028448480020698153 -0.02399986356623937 -2.0958257078984577e-06" rpy="0 0 0"/>
    <mass value="0.15678652750508332"/>
    <inertia ixx="3.8e-05" iyy="3.9e-05" izz="3.5e-05" ixy="-0.0" iyz="0.0" ixz="-0.0"/>
  </inertial>
  <visual>
    <origin xyz="-0.0108 -0.024 -0.103" rpy="0 0 0"/>
    <geometry>
      <mesh filename="package://arm_description/meshes/STL/VDB/link7.stl" scale="0.001 0.001 0.001"/>
    </geometry>
    <material name="opaque160160160"/>
  </visual>
  <collision>
    <origin xyz="-0.0108 -0.024 -0.103" rpy="0 0 0"/>
    <geometry>
      <mesh filename="package://arm_description/meshes/STL/VDB/link7.stl" scale="0.001 0.001 0.001"/>
    </geometry>
  </collision>
</link>

<link name="link8">
  <inertial>
    <origin xyz="0.006337791282976783 0.014437861844293989 -0.002533555574269944" rpy="0 0 0"/>
    <mass value="0.41604327739339353"/>
    <inertia ixx="0.000417" iyy="0.000227" izz="0.000586" ixy="-1.7e-05" iyz="3.7e-05" ixz="6e-06"/>
  </inertial>
  <visual>
    <origin xyz="-0.0328 0.0 -0.103" rpy="0 0 0"/>
    <geometry>
      <mesh filename="package://arm_description/meshes/STL/VDB/link8.stl" scale="0.001 0.001 0.001"/>
    </geometry>
    <material name="opaque210200"/>
  </visual>
  <collision>
    <origin xyz="-0.0328 0.0 -0.103" rpy="0 0 0"/>
    <geometry>
      <mesh filename="package://arm_description/meshes/STL/VDB/link8.stl" scale="0.001 0.001 0.001"/>
    </geometry>
  </collision>
</link>

<link name="link12">
  <inertial>
    <origin xyz="-0.0070040483790297925 -8.487575241938883e-08 -8.071878474513738e-07" rpy="0 0 0"/>
    <mass value="0.019850481866978086"/>
    <inertia ixx="1e-06" iyy="1e-06" izz="1e-06" ixy="-0.0" iyz="0.0" ixz="-0.0"/>
  </inertial>
  <visual>
    <origin xyz="-0.0664 -0.05 -0.103" rpy="0 0 0"/>
    <geometry>
      <mesh filename="package://arm_description/meshes/STL/VDB/link12.stl" scale="0.001 0.001 0.001"/>
    </geometry>
    <material name="opaque898989"/>
  </visual>
  <collision>
    <origin xyz="-0.0664 -0.05 -0.103" rpy="0 0 0"/>
    <geometry>
      <mesh filename="package://arm_description/meshes/STL/VDB/link12.stl" scale="0.001 0.001 0.001"/>
    </geometry>
  </collision>
</link>

<link name="link10">
  <inertial>
    <origin xyz="0.02573313617415028 -0.03390025109466069 0.0052187897794312155" rpy="0 0 0"/>
    <mass value="0.1633987484930479"/>
    <inertia ixx="3.2e-05" iyy="7.7e-05" izz="7.6e-05" ixy="1.2e-05" iyz="5e-06" ixz="-8e-06"/>
  </inertial>
  <visual>
    <origin xyz="-0.0641 -0.0325 -0.0959" rpy="0 0 0"/>
    <geometry>
      <mesh filename="package://arm_description/meshes/STL/VDB/link10.stl" scale="0.001 0.001 0.001"/>
    </geometry>
    <material name="opaque252525"/>
  </visual>
  <collision>
    <origin xyz="-0.0641 -0.0325 -0.0959" rpy="0 0 0"/>
    <geometry>
      <mesh filename="package://arm_description/meshes/STL/VDB/link10.stl" scale="0.001 0.001 0.001"/>
    </geometry>
  </collision>
</link>

<link name="link9">
  <inertial>
    <origin xyz="0.0257331361554268 0.033900251075823624 -0.005218789736564436" rpy="0 0 0"/>
    <mass value="0.16339874859628656"/>
    <inertia ixx="3.2e-05" iyy="7.7e-05" izz="7.6e-05" ixy="-1.2e-05" iyz="5e-06" ixz="8e-06"/>
  </inertial>
  <visual>
    <origin xyz="-0.0641 0.0325 -0.1101" rpy="0 0 0"/>
    <geometry>
      <mesh filename="package://arm_description/meshes/STL/VDB/link9.stl" scale="0.001 0.001 0.001"/>
    </geometry>
    <material name="opaque1965339"/>
  </visual>
  <collision>
    <origin xyz="-0.0641 0.0325 -0.1101" rpy="0 0 0"/>
    <geometry>
      <mesh filename="package://arm_description/meshes/STL/VDB/link9.stl" scale="0.001 0.001 0.001"/>
    </geometry>
  </collision>
</link>

<!-- Attach base_link to world -->
<link name="world"/>

<joint name="world_to_base_link" type="fixed">
     <parent link="world"/>
     <child link="base_link"/>
</joint>

<joint name="base_link-link11" type="continuous">
  <origin xyz="-0.069 0.0 0.006" rpy="0 0 0"/>
  <parent link="base_link"/>
  <child link="link11"/>
  <axis xyz="0.0 0.0 1.0"/>
  <dynamics damping="0.5" friction="1.0"/>
</joint>

<joint name="base_link-link1" type="revolute">
  <origin xyz="0.0 0.0 0.0105" rpy="0 0 0"/>
  <parent link="base_link"/>
  <child link="link1"/>
  <axis xyz="0.0 0.0 1.0"/>
  <limit upper="3.141593" lower="-3.141593" effort="100" velocity="100"/>
  <dynamics damping="0.5" friction="1.0"/>

</joint>
  <!--
    EXAMPLE FROM https://github.com/PickNikRobotics/stretch_ros/blob/stretch_xacro_ign/stretch_description/urdf/stretch_main.xacro
    <limit effort="100" lower="-1.75" upper="4.0" velocity="1.0"/>
    <dynamics damping="${joint_damping}" friction="${joint_friction}" spring_reference="${joint_spring_reference}" spring_stiffness="{joint_spring_stiffness}"/>
  -->


<joint name="link1-link2" type="revolute">
  <origin xyz="0.045 -0.017 0.0515" rpy="0 0 0"/>
  <parent link="link1"/>
  <child link="link2"/>
  <axis xyz="0.0 1.0 0.0"/>
  <limit upper="4.101524" lower="-4.101524" effort="100" velocity="100"/>
<!--  <limit upper="4.101524" lower="0.0" effort="100" velocity="100"/>-->
  <dynamics damping="0.5" friction="1.0"/>
</joint>

<joint name="link2-link3" type="revolute">
  <origin xyz="-0.2 0.0 0.015" rpy="0 0 0"/>
  <parent link="link2"/>
  <child link="link3"/>
  <axis xyz="0.0 1.0 0.0"/>
  <limit upper="2.792527" lower="-2.792527" effort="100" velocity="100"/>
<!--  <limit upper="0.0" lower="-2.792527" effort="100" velocity="100"/>-->
  <dynamics damping="0.5" friction="1.0"/>
</joint>

<joint name="link3-link4" type="revolute">
  <origin xyz="0.1089 0.017 0.026" rpy="0 0 0"/>
  <parent link="link3"/>
  <child link="link4"/>
  <axis xyz="1.0 0.0 0.0"/>
  <limit upper="3.141593" lower="-3.141593" effort="100" velocity="100"/>
  <dynamics damping="2.5" friction="5.0"/>
</joint>

<joint name="link4-link5" type="continuous">
  <origin xyz="0.0569 -0.024 0.0" rpy="0 0 0"/>
  <parent link="link4"/>
  <child link="link5"/>
  <axis xyz="0.0 1.0 0.0"/>
  <dynamics damping="5.0" friction="10.0"/>
</joint>

<joint name="link4-link6" type="continuous">
  <origin xyz="0.0569 0.024 0.0" rpy="0 0 0"/>
  <parent link="link4"/>
  <child link="link6"/>
  <axis xyz="0.0 1.0 0.0"/>
  <dynamics damping="5.0" friction="10.0"/>
</joint>

<joint name="link4-link7" type="revolute">
  <origin xyz="0.0569 0.024 0.0" rpy="0 0 0"/>
  <parent link="link4"/>
  <child link="link7"/>
  <axis xyz="0.0 1.0 0.0"/>
  <limit upper="1.745329" lower="-1.745329" effort="100" velocity="100"/>
  <dynamics damping="5.0" friction="10.0"/>
</joint>

<joint name="link7-link8" type="revolute">
  <origin xyz="0.022 -0.024 0.0" rpy="0 0 0"/>
  <parent link="link7"/>
  <child link="link8"/>
  <axis xyz="1.0 0.0 0.0"/>
  <limit upper="3.141593" lower="-3.141593" effort="100" velocity="100"/>
  <dynamics damping="5.0" friction="10.0"/>
</joint>

<joint name="link8-link12" type="continuous">
  <origin xyz="0.0336 0.05 0.0" rpy="0 0 0"/>
  <parent link="link8"/>
  <child link="link12"/>
  <axis xyz="1.0 0.0 0.0"/>
  <dynamics damping="1.0" friction="2.0"/>
</joint>

<joint name="link8-link10" type="prismatic">
  <origin xyz="0.0313 0.0325 -0.0071" rpy="0 0 0"/>
  <parent link="link8"/>
  <child link="link10"/>
  <axis xyz="0.0 1.0 0.0"/>
  <limit upper="0.0" lower="-0.051" effort="100" velocity="100"/>
  <dynamics damping="1.0" friction="2.0"/>
</joint>

<joint name="link8-link9" type="prismatic">
  <origin xyz="0.0313 -0.0325 0.0071" rpy="0 0 0"/>
  <parent link="link8"/>
  <child link="link9"/>
  <axis xyz="0.0 1.0 0.0"/>
  <limit upper="0.051" lower="0.0" effort="100" velocity="100"/>
<!--  <dynamics damping="1.0" friction="2.0"/>-->
</joint>



  <ros2_control name="arm_controller" type="system">
  <hardware>
    <plugin>ign_ros2_control/IgnitionSystem</plugin>
  </hardware>

<joint name="link1-link2">
  <command_interface name="position"/>
    <state_interface name="position">
    <param name="initial_value">0</param>
    </state_interface>
    <state_interface name="velocity"/>
</joint>

<joint name="base_link-link1">
  <command_interface name="position"/>
    <state_interface name="position">
    <param name="initial_value">0</param>
    </state_interface>
    <state_interface name="velocity"/>
</joint>

<joint name="link2-link3">
  <command_interface name="position"/>
    <state_interface name="position">
    <param name="initial_value">0</param>
    </state_interface>
    <state_interface name="velocity"/>
</joint>
<joint name="link8-link9">
    <param name="initial_position">0.0</param>
    <command_interface name="position" />
    <state_interface name="position"/>
    <state_interface name="velocity"/>
</joint>
<joint name="link8-link10">
    <param name="mimic">link8-link9</param>
    <param name="multiplier">-1</param>
    <command_interface name="position" />
    <state_interface name="position"/>
    <state_interface name="velocity"/>
</joint>
</ros2_control>

  <gazebo>
    <plugin filename="libignition-gazebo-joint-state-publisher-system.so" name="ignition::gazebo::systems::JointStatePublisher"/>


        <plugin filename="ign_ros2_control-system" name="ign_ros2_control::IgnitionROS2ControlPlugin">
            <robot_sim_type>ign_ros2_control/IgnitionSystem</robot_sim_type>
            <parameters>/home/asimovo/src/stella_arm_controllers/config/controller_configuration_gripper.yaml</parameters>            
        </plugin>
    




<!--  &lt;!&ndash;    TRAJECTORY CONTROL&ndash;&gt;-->
<!--  <plugin filename="libignition-gazebo-joint-trajectory-controller-system.so" name="ignition::gazebo::systems::JointTrajectoryController">-->
<!--      <topic>/arm_joint_trajectory_controller/joint_trajectory</topic>-->

<!--      <joint_name>base_link-link1</joint_name>-->
<!--      <initial_position>0</initial_position>-->
<!--      <position_p_gain>100</position_p_gain>-->
<!--      <position_d_gain>10</position_d_gain>-->
<!--      <position_i_gain>1</position_i_gain>-->
<!--      <position_i_min>-1</position_i_min>-->
<!--      <position_i_max>1</position_i_max>-->
<!--      <position_cmd_min>-50</position_cmd_min>-->
<!--      <position_cmd_max>50</position_cmd_max>-->

<!--      <joint_name>link1-link2</joint_name>-->
<!--      <initial_position>0</initial_position>-->
<!--      <position_p_gain>100</position_p_gain>-->
<!--      <position_d_gain>10</position_d_gain>-->
<!--      <position_i_gain>1</position_i_gain>-->
<!--      <position_i_min>-1</position_i_min>-->
<!--      <position_i_max>1</position_i_max>-->
<!--      <position_cmd_min>-50</position_cmd_min>-->
<!--      <position_cmd_max>50</position_cmd_max>-->

<!--      <joint_name>link2-link3</joint_name>-->
<!--      <initial_position>0</initial_position>-->
<!--      <position_p_gain>100</position_p_gain>-->
<!--      <position_d_gain>10</position_d_gain>-->
<!--      <position_i_gain>1</position_i_gain>-->
<!--      <position_i_min>-1</position_i_min>-->
<!--      <position_i_max>1</position_i_max>-->
<!--      <position_cmd_min>-50</position_cmd_min>-->
<!--      <position_cmd_max>50</position_cmd_max>-->

<!--  </plugin>-->





<!--  POSITION CONTROL-->
<!--    <plugin filename="ignition-gazebo-joint-position-controller-system" name="ignition::gazebo::systems::JointPositionController">-->
<!--      <joint_name>base_link-link1</joint_name>-->
<!--      <topic>control_base_link_link1</topic>-->
<!--      <p_gain>100</p_gain>-->
<!--      <d_gain>10</d_gain>-->
<!--      <i_gain>1</i_gain>-->
<!--      <i_min>-1</i_min>-->
<!--      <i_max>1</i_max>-->
<!--      <cmd_min>-50</cmd_min>-->
<!--      <cmd_max>50</cmd_max>-->
<!--    </plugin>-->

<!--        <plugin filename="ignition-gazebo-joint-position-controller-system" name="ignition::gazebo::systems::JointPositionController">-->
<!--      <joint_name>link1-link2</joint_name>-->
<!--      <topic>control_link1_link2</topic>-->
<!--      <p_gain>100</p_gain>-->
<!--      <d_gain>10</d_gain>-->
<!--      <i_gain>1</i_gain>-->
<!--      <i_min>-1</i_min>-->
<!--      <i_max>1</i_max>-->
<!--      <cmd_min>-50</cmd_min>-->
<!--      <cmd_max>50</cmd_max>-->
<!--    </plugin>-->

<!--        <plugin filename="ignition-gazebo-joint-position-controller-system" name="ignition::gazebo::systems::JointPositionController">-->
<!--      <joint_name>link2-link3</joint_name>-->
<!--      <topic>control_link2_link3</topic>-->
<!--      <p_gain>100</p_gain>-->
<!--      <d_gain>10</d_gain>-->
<!--      <i_gain>1</i_gain>-->
<!--      <i_min>-1</i_min>-->
<!--      <i_max>1</i_max>-->
<!--      <cmd_min>-50</cmd_min>-->
<!--      <cmd_max>50</cmd_max>-->
<!--    </plugin>-->

<!--        <plugin filename="ignition-gazebo-joint-position-controller-system" name="ignition::gazebo::systems::JointPositionController">-->
<!--      <joint_name>link3-link4</joint_name>-->
<!--      <topic>control_link3_link4</topic>-->
<!--      <p_gain>50</p_gain>-->
<!--      <d_gain>4</d_gain>-->
<!--      <i_gain>3</i_gain>-->
<!--      <i_min>-15</i_min>-->
<!--      <i_max>15</i_max>-->
<!--      <cmd_min>-50</cmd_min>-->
<!--      <cmd_max>50</cmd_max>-->
<!--    </plugin>-->

<!--&lt;!&ndash;        <plugin filename="ignition-gazebo-joint-position-controller-system" name="ignition::gazebo::systems::JointPositionController">&ndash;&gt;-->
<!--&lt;!&ndash;      <joint_name>link4-link5</joint_name>&ndash;&gt;-->
<!--&lt;!&ndash;      <topic>control_link4_link5</topic>&ndash;&gt;-->
<!--&lt;!&ndash;      <p_gain>100</p_gain>&ndash;&gt;-->
<!--&lt;!&ndash;      <d_gain>10</d_gain>&ndash;&gt;-->
<!--&lt;!&ndash;      <i_gain>0</i_gain>&ndash;&gt;-->
<!--&lt;!&ndash;      <i_min>-1</i_min>&ndash;&gt;-->
<!--&lt;!&ndash;      <i_max>1</i_max>&ndash;&gt;-->
<!--&lt;!&ndash;      <cmd_min>-50</cmd_min>&ndash;&gt;-->
<!--&lt;!&ndash;      <cmd_max>50</cmd_max>&ndash;&gt;-->
<!--&lt;!&ndash;    </plugin>&ndash;&gt;-->

<!--&lt;!&ndash;        <plugin filename="ignition-gazebo-joint-position-controller-system" name="ignition::gazebo::systems::JointPositionController">&ndash;&gt;-->
<!--&lt;!&ndash;      <joint_name>link4-link6</joint_name>&ndash;&gt;-->
<!--&lt;!&ndash;      <topic>control_link4_link6</topic>&ndash;&gt;-->
<!--&lt;!&ndash;      <p_gain>100</p_gain>&ndash;&gt;-->
<!--&lt;!&ndash;      <d_gain>10</d_gain>&ndash;&gt;-->
<!--&lt;!&ndash;      <i_gain>0</i_gain>&ndash;&gt;-->
<!--&lt;!&ndash;      <i_min>-1</i_min>&ndash;&gt;-->
<!--&lt;!&ndash;      <i_max>1</i_max>&ndash;&gt;-->
<!--&lt;!&ndash;      <cmd_min>-50</cmd_min>&ndash;&gt;-->
<!--&lt;!&ndash;      <cmd_max>50</cmd_max>&ndash;&gt;-->
<!--&lt;!&ndash;    </plugin>&ndash;&gt;-->

<!--            <plugin filename="ignition-gazebo-joint-position-controller-system" name="ignition::gazebo::systems::JointPositionController">-->
<!--      <joint_name>link4-link7</joint_name>-->
<!--      <topic>control_link4_link7</topic>-->
<!--      <p_gain>100</p_gain>-->
<!--      <d_gain>8</d_gain>-->
<!--      <i_gain>1</i_gain>-->
<!--      <i_min>-5</i_min>-->
<!--      <i_max>5</i_max>-->
<!--      <cmd_min>-50</cmd_min>-->
<!--      <cmd_max>50</cmd_max>-->
<!--    </plugin>-->

<!--&lt;!&ndash;    <plugin filename="ignition-gazebo-joint-position-controller-system" name="ignition::gazebo::systems::JointPositionController">&ndash;&gt;-->
<!--&lt;!&ndash;      <joint_name>link7-link8</joint_name>&ndash;&gt;-->
<!--&lt;!&ndash;      <topic>control_link7_link8</topic>&ndash;&gt;-->
<!--&lt;!&ndash;      <p_gain>100</p_gain>&ndash;&gt;-->
<!--&lt;!&ndash;      <d_gain>10</d_gain>&ndash;&gt;-->
<!--&lt;!&ndash;      <i_gain>0</i_gain>&ndash;&gt;-->
<!--&lt;!&ndash;      <i_min>-1</i_min>&ndash;&gt;-->
<!--&lt;!&ndash;      <i_max>1</i_max>&ndash;&gt;-->
<!--&lt;!&ndash;      <cmd_min>-50</cmd_min>&ndash;&gt;-->
<!--&lt;!&ndash;      <cmd_max>50</cmd_max>&ndash;&gt;-->
<!--&lt;!&ndash;    </plugin>&ndash;&gt;-->

<!--&lt;!&ndash;    <plugin filename="ignition-gazebo-joint-position-controller-system" name="ignition::gazebo::systems::JointPositionController">&ndash;&gt;-->
<!--&lt;!&ndash;      <joint_name>link8-link12</joint_name>&ndash;&gt;-->
<!--&lt;!&ndash;      <topic>control_link8_link12</topic>&ndash;&gt;-->
<!--&lt;!&ndash;      <p_gain>100</p_gain>&ndash;&gt;-->
<!--&lt;!&ndash;      <d_gain>10</d_gain>&ndash;&gt;-->
<!--&lt;!&ndash;      <i_gain>0</i_gain>&ndash;&gt;-->
<!--&lt;!&ndash;      <i_min>-1</i_min>&ndash;&gt;-->
<!--&lt;!&ndash;      <i_max>1</i_max>&ndash;&gt;-->
<!--&lt;!&ndash;      <cmd_min>-50</cmd_min>&ndash;&gt;-->
<!--&lt;!&ndash;      <cmd_max>50</cmd_max>&ndash;&gt;-->
<!--&lt;!&ndash;    </plugin>&ndash;&gt;-->

<!--&lt;!&ndash;    <plugin filename="ignition-gazebo-joint-position-controller-system" name="ignition::gazebo::systems::JointPositionController">&ndash;&gt;-->
<!--&lt;!&ndash;      <joint_name>link8-link10</joint_name>&ndash;&gt;-->
<!--&lt;!&ndash;      <topic>control_link8_link10</topic>&ndash;&gt;-->
<!--&lt;!&ndash;      <p_gain>100</p_gain>&ndash;&gt;-->
<!--&lt;!&ndash;      <d_gain>10</d_gain>&ndash;&gt;-->
<!--&lt;!&ndash;      <i_gain>0</i_gain>&ndash;&gt;-->
<!--&lt;!&ndash;      <i_min>-1</i_min>&ndash;&gt;-->
<!--&lt;!&ndash;      <i_max>1</i_max>&ndash;&gt;-->
<!--&lt;!&ndash;      <cmd_min>-50</cmd_min>&ndash;&gt;-->
<!--&lt;!&ndash;      <cmd_max>50</cmd_max>&ndash;&gt;-->
<!--&lt;!&ndash;    </plugin>&ndash;&gt;-->

<!--    <plugin filename="ignition-gazebo-joint-position-controller-system" name="ignition::gazebo::systems::JointPositionController">-->
<!--      <joint_name>link8-link9</joint_name>-->
<!--      <topic>control_link8_link9</topic>-->
<!--      <p_gain>25</p_gain>-->
<!--      <d_gain>2</d_gain>-->
<!--      <i_gain>1</i_gain>-->
<!--      <i_min>-5</i_min>-->
<!--      <i_max>5</i_max>-->
<!--      <cmd_min>-50</cmd_min>-->
<!--      <cmd_max>50</cmd_max>-->
<!--    </plugin>-->
  </gazebo>

</robot>
